<?xml version="1.0"?>

<robot xmlns:xacro="http://ros.org/wiki/xacro" name="tekbot_wheel">

    <!-- Define the shape of the robot's two back wheels in meters -->
    <xacro:property name="wheel_radius" value="0.08"/>
    <xacro:property name="wheel_width" value="0.03"/>
    <!-- Define the gap between the wheel and chassis along y-axis in meters -->
    <xacro:property name="wheel_ygap" value="0.005"/>

    <!-- Position the wheels along the z-axis -->
    <xacro:property name="wheel_zoff" value="0.05"/>

    <!-- Position the wheels along the x-axis -->
    <xacro:property name="wheel_xoff" value="0.10"/>
    <xacro:property name="base_width" value="0.25"/>
    <xacro:include filename="$(find tekbot_description)//urdf/cylinder.urdf.xacro"/>
    
    <!-- *********************** DRIVE WHEELS ******************************  -->
    <xacro:macro name="tekbot_wheel" params="parent prefix x_reflect y_reflect">
    
        <link name="${prefix}_link">
            
            <visual>
                <origin xyz="0 0 0" rpy="${pi/2} 0 0"/>
                <geometry>
                    <cylinder radius="${wheel_radius}" length="${wheel_width}"/>
                </geometry>

                <!-- <geometry>
                    <mesh filename="file://$(find tekbot_description)/meshes/tire.stl"/>
                </geometry> -->
                
                <material name="Gray">
                    <color rgba="0.5 0.5 0.5 1.0"/>
                </material>
            </visual>

            <collision>
                <origin xyz="0 0 0" rpy="${pi/2} 0 0"/> 
                <geometry>
                    <cylinder radius="${wheel_radius}" length="${wheel_width}"/>
                </geometry>
            </collision>

            <xacro:cylinder_inertia m="0.5" r="${wheel_radius}" h="${wheel_width}"/>
        </link>

        <!-- Connect the wheels to the base_link at the appropriate location, and  define a continuous joint to allow the wheels to freely rotate about an axis -->
        <joint name="${prefix}_joint" type="continuous">
            <parent link="${parent}"/>
            <child link="${prefix}_link"/>
            <origin xyz="${x_reflect*wheel_xoff} ${y_reflect*(base_width/2+wheel_ygap)} ${-wheel_zoff}" rpy="0 0 0"/>
            <axis xyz="0 1 0"/>
        </joint>

        <transmission name="${prefix}_trans">
            <type>transmission_interface/SimpleTransmission</type>
            <joint name="${prefix}_joint">
            <hardwareInterface>hardware_interface/PositionJointInterface</hardwareInterface>
            </joint>
            <actuator name="${prefix}_motor">
            <hardwareInterface>hardware_interface/PositionJointInterface</hardwareInterface>
            </actuator>
        </transmission>

    </xacro:macro>
        
</robot>
